<?xml version="1.0" ?>
<sdf version="1.7">
    <model name='vehicle_blue' canonical_link='chassis'>
        <!--pose relative_to="">0 0 0 0 0 0</pose-->   <!--the pose is relative to the world by default-->
        <link name='chassis'>   <!--todo add canonical link, remove pose-->
            <pose relative_to=__model__>1 1 1 0 0 0</pose> <!--question: we can't refer to world due to scope-->
            <inertial> <!--inertial properties of the link mass, inertia matix-->
                <mass>1.14395</mass>
                <inertia>
                    <ixx>0.126164</ixx>
                    <ixy>0</ixy>
                    <ixz>0</ixz>
                    <iyy>0.416519</iyy>
                    <iyz>0</iyz>
                    <izz>0.481014</izz>
                </inertia>
            </inertial>
            <visual name='visual'>
                <geometry>
                    <box>
                        <size>2.0 1 0.5</size> <!--question: this size is in meter-->
                    </box>
                </geometry>
                <!--let's add color to our link-->
                <material>
                    <ambient>0.0 0.0 1.0 1</ambient>
                    <diffuse>0.0 0.0 1.0 1</diffuse>
                    <specular>0.0 0.0 1.0 1</specular>
                </material>
            </visual>
            <collision name='collision'> <!--todo: describe why we need the collision-->
                <geometry>
                    <box>
                        <size>2.0 1 0.5</size>
                    </box>
                </geometry>
            </collision>
        </link>
        <!--let's build the left wheel-->
        <link name='left_wheel'> <!--todo: change the inertia matrix-->
            <pose relative_to='chassis'>-0.5 0.6 0 -1.5707 0 0</pose> <!--angles are in radian-->
            <inertial>
                <mass>2</mass>
                <inertia>
                    <ixx>0.145833</ixx>
                    <ixy>0</ixy>
                    <ixz>0</ixz>
                    <iyy>0.145833</iyy>
                    <iyz>0</iyz>
                    <izz>0.125</izz>
                </inertia>
            </inertial>
            <visual name='visual'>
                <geometry>
                    <cylinder>
                        <radius>0.4</radius> <!--todo edit the collision too-->
                        <length>0.2</length>
                    </cylinder>
                </geometry>
                <material>
                    <ambient>1.0 0.0 0.0 1</ambient>
                    <diffuse>1.0 0.0 0.0 1</diffuse>
                    <specular>1.0 0.0 0.0 1</specular>
                </material>
            </visual>
            <collision name='collision'>
                <geometry>
                    <cylinder>
                        <radius>0.3</radius>
                        <length>0.2</length>
                    </cylinder>
                </geometry>
            </collision>
        </link>   
        <!--copy and paste for right wheel but change position-->
        <link name='right_wheel'> <!--todo: change the inertia matrix-->
            <pose relative_to="chassis">-0.5 -0.6 0 -1.5707 0 0</pose> <!--angles are in radian-->
            <inertial>
                <mass>2</mass>
                <inertia>
                    <ixx>0.145833</ixx>
                    <ixy>0</ixy>
                    <ixz>0</ixz>
                    <iyy>0.145833</iyy>
                    <iyz>0</iyz>
                    <izz>0.125</izz>
                </inertia>
            </inertial>
            <visual name='visual'>
                <geometry>
                    <cylinder>
                        <radius>0.4</radius>
                        <length>0.2</length>
                    </cylinder>
                </geometry>
                <material>
                    <ambient>1.0 0.0 0.0 1</ambient>
                    <diffuse>1.0 0.0 0.0 1</diffuse>
                    <specular>1.0 0.0 0.0 1</specular>
                </material>
            </visual>
            <collision name='collision'>
                <geometry>
                    <cylinder>
                        <radius>0.4</radius>
                        <length>0.2</length>
                    </cylinder>
                </geometry>
            </collision>

        </link>

        <!--caster wheel-->
        <link name='caster'>
            <pose relative_to='F'/> <!--todo: define a frame and use in the visual and collision-->
            <inertial>
                <mass>1</mass>
                <inertia>
                    <ixx>0.1</ixx>
                    <ixy>0</ixy>
                    <ixz>0</ixz>
                    <iyy>0.1</iyy>
                    <iyz>0</iyz>
                    <izz>0.1</izz>
                </inertia>
            </inertial>
            <visual name='visual'>
                <geometry>
                    <sphere>
                        <radius>0.2</radius>
                    </sphere>
                </geometry>
                <material>
                    <ambient>0.0 1 0.0 1</ambient>
                    <diffuse>0.0 1 0.0 1 1</diffuse>
                    <specular>0.0 1 0.0 1</specular>
                </material>
            </visual>
            <collision name='collision'>
                <geometry>
                    <sphere>
                        <radius>0.2</radius>
                    </sphere>
                </geometry>
            </collision>
        </link>

        <frame name="F" attached_to='chassis'>
            <pose>0.8 0 -0.45 0 0 0</pose>
        </frame>
        
        <!--connecting these links together using joints-->
        <joint name='left_wheel_joint' type='revolute'>
            <pose relative_to='chassis'>0.0 0.7 0 0 0 0</pose>
            <parent>chassis</parent>
            <child>left_wheel</child>
            <axis>
                <xyz expressed_in=__model__>0 0 1</xyz>
                <limit>
                    <lower>-1.79769e+308</lower>
                    <upper>1.79769e+308</upper>
                </limit>
            </axis>
        </joint>

        <joint name='right_wheel_joint' type='revolute'>
            <pose relative_to='chassis'>0.0 -0.7 0 0 0 0</pose>
            <parent>chassis</parent>
            <child>right_wheel</child>
            <axis>
                <xyz>0 0 1</xyz>
                <limit>
                    <lower>-1.79769e+308</lower>
                    <upper>1.79769e+308</upper>
                </limit>
            </axis>
        </joint>

        <!--different type of joints ball joint--> <!--defult value is the child-->
        <joint name='caster_wheel' type='ball'>
            <parent>chassis</parent>
            <child>caster</child>
        </joint>
        
    </model>
</sdf> 